Workbook

Sheet Ước tính chi phí
E3: Chi phí cố định FC (nghìn vnđ)
A4: Chi phí | B4: 2025-2026 | P4: STT | Q4: Tên tài sản | R4: Loại tài sản | S4: Đơn vị | T4: Đơn giá | U4: Số lượng | V4: Tổng tiền | W4: Thời gian sử dụng (tháng) | X4: Khấu hao tài sản cố định | Y4: Phân bổ chi phí CCDC
B5: T9 | C5: T10 | D5: T11 | E5: T12 | F5: T1 | G5: T2 | H5: T3 | I5: T4 | J5: T5 | K5: T6 | L5: T7 | M5: T8 | T5: (1000đ)
A6: Thuê mặt bằng | B6: 100000 | C6: 100000 | D6: 100000 | E6: 100000 | F6: 100000 | G6: 100000 | H6: 100000 | I6: 100000 | J6: 100000 | K6: 100000 | L6: 100000 | M6: 100000 | P6: 1 | Q6: Máy pha cà phê 2 group | R6: TSCĐ | S6: Cái | T6: 35000 | U6: 1 | V6: 35000 | W6: 60
A7: Trả lương | B7: 89000 | C7: 89000 | D7: 89000 | E7: 89000 | F7: 89000 | G7: 89000 | H7: 89000 | I7: 89000 | J7: 89000 | K7: 89000 | L7: 89000 | M7: 89000 | P7: 2 | Q7: Máy xay cà phê | R7: CCDC | S7: Cái | T7: 8000 | U7: 1 | V7: 8000 | W7: 24 | Y7: =V7/W7 -> 333.33333
A8: Khấu hao, phân bổ (máy pha, nội thất, thiết bị) | B8: 10082 | C8: 10082 | D8: 10082 | E8: 10082 | F8: 10082 | G8: 10082 | H8: 10082 | I8: 10082 | J8: 10082 | K8: 10082 | L8: 10082 | M8: 10082 | P8: 3 | Q8: Máy đánh sữa / tạo bọt | R8: CCDC | S8: Cái | T8: 2500 | U8: 1 | V8: 2500 | W8: 24 | Y8: =V8/W8 -> 104.16667
A9: Thuế môn bài | B9: 0 | C9: 1000 | D9: 0 | E9: 0 | F9: 0 | G9: 0 | H9: 0 | I9: 0 | J9: 0 | K9: 0 | L9: 0 | M9: 0 | P9: 4 | Q9: Ấm đun nước siêu tốc công nghiệp | R9: CCDC | S9: Cái | T9: 2000 | U9: 1 | V9: 2000 | W9: 24 | Y9: =V9/W9 -> 83.333333
A10: Phí dkkd | B10: 200 | C10: 0 | D10: 0 | E10: 0 | F10: 0 | G10: 0 | H10: 0 | I10: 0 | J10: 0 | K10: 0 | L10: 0 | M10: 0 | P10: 5 | Q10: Bình ủ trà / bình ủ sữa | R10: CCDC | S10: Cái | T10: 2500 | U10: 2 | V10: 5000 | W10: 24 | Y10: =V10/W10 -> 208.33333
A11: Marketing | B11: 26000 | C11: 10000 | D11: 10000 | E11: 10000 | F11: 8000 | G11: 8000 | H11: 8000 | I11: 8000 | J11: 8000 | K11: 8000 | L11: 8000 | M11: 8000 | P11: 6 | Q11: Máy lắc trà / bình shaker | R11: CCDC | S11: Bộ | T11: 1500 | U11: 2 | V11: 3000 | W11: 24 | Y11: =V11/W11 -> 125
A12: Điện nước vp | B12: 6000 | C12: 6000 | D12: 6000 | E12: 6000 | F12: 6000 | G12: 6000 | H12: 6000 | I12: 6000 | J12: 6000 | K12: 6000 | L12: 6000 | M12: 6000 | P12: 7 | Q12: Máy hàn miệng ly nhựa | R12: CCDC | S12: Cái | T12: 4000 | U12: 1 | V12: 4000 | W12: 24 | Y12: =V12/W12 -> 166.66667
A13: Khác (bảo trì, vệ sinh, wifi, dụng cụ…) | B13: 3000 | C13: 3000 | D13: 3000 | E13: 3000 | F13: 3000 | G13: 3000 | H13: 3000 | I13: 3000 | J13: 3000 | K13: 3000 | L13: 3000 | M13: 3000 | P13: 8 | Q13: Máy định lượng đường & sữa | R13: CCDC | S13: Cái | T13: 6000 | U13: 1 | V13: 6000 | W13: 24 | Y13: =V13/W13 -> 250
A14: Tổng FC | B14: 234282 | C14: 219282 | D14: 218282 | E14: 218282 | F14: 218282 | G14: 218282 | H14: 218282 | I14: 218282 | J14: 218282 | K14: 218282 | L14: 218282 | M14: 218282 | P14: 9 | Q14: Bình pha trà / bình lọc trà | R14: CCDC | S14: Bộ | T14: 2000 | U14: 2 | V14: 4000 | W14: 24 | Y14: =V14/W14 -> 166.66667
A15: Tổng FC Cả Năm | B15: =SUM(B14:M14) -> 2636384 | P15: 11 | Q15: Tủ lạnh trữ sữa | R15: CCDC | S15: Cái | T15: 20000 | U15: 1 | V15: 20000 | W15: 24 | Y15: =V15/W15 -> 833.33333
A16: Ước tính chi phí | P16: 13 | Q16: Tủ đông nhỏ trữ đá | R16: CCDC | S16: Cái | T16: 15000 | U16: 1 | V16: 15000 | W16: 24 | Y16: =V16/W16 -> 625
P17: 14 | Q17: Máy xay sinh tố công nghiệp | R17: CCDC | S17: Cái | T17: 2000 | U17: 1 | V17: 2000 | W17: 24 | Y17: =V17/W17 -> 83.333333
B18: T9 | C18: T10 | D18: T11 | E18: T12 | F18: T1 | G18: T2 | H18: T3 | I18: T4 | J18: T5 | K18: T6 | L18: T7 | M18: T8 | P18: 16 | Q18: Nồi nấu trân châu tự động | R18: CCDC | S18: Cái | T18: 8000 | U18: 1 | V18: 8000 | W18: 24 | Y18: =V18/W18 -> 333.33333
A19: Chi phí cố định | B19: =B14 -> 234282 | C19: =SUM(C14:C18) -> 219282 | D19: =SUM(D14:D18) -> 218282 | E19: =SUM(E14:E18) -> 218282 | F19: =SUM(F14:F18) -> 218282 | G19: =G14 -> 218282 | H19: =SUM(H14:H18) -> 218282 | I19: =SUM(I14:I18) -> 218282 | J19: =SUM(J14:J18) -> 218282 | K19: =SUM(K14:K18) -> 218282 | L19: =SUM(L14:L18) -> 218282 | M19: =SUM(M14:M18) -> 218282 | P19: 17 | Q19: Kệ inox để máy pha chế | R19: CCDC | S19: Cái | T19: 1500 | U19: 1 | V19: 1500 | W19: 24 | Y19: =V19/W19 -> 62.5
A20: Chi phí biến đổi | B20: =C173 -> 86210 | C20: =D173 -> 86061 | D20: =E173 -> 86219 | E20: =F173 -> 86534 | F20: =G173 -> 87830 | G20: =H173 -> 87917 | H20: =I173 -> 87450 | I20: =J173 -> 87561 | ... M20: =N173 -> 88209 | P20: 18 | Q20: Kệ trưng bày snack / bánh | R20: CCDC | S20: Cái | T20: 2000 | U20: 1 | V20: 2000 | W20: 24 | Y20: =V20/W20 -> 83.333333
A21: Tổng chi phí hàng tháng | B21: =SUM(B19:B20) -> 320492 | C21: =SUM(C19:C20) -> 305343 | D21: =SUM(D19:D20) -> 304501 | E21: =SUM(E19:E20) -> 304816 | F21: =SUM(F19:F20) -> 306112 | G21: =SUM(G19:G20) -> 306199 | H21: =SUM(H19:H20) -> 305732 | I21: =SUM(I19:I20) -> 305843 | ... M21: =SUM(M19:M20) -> 306491 | P21: 19 | Q21: Bồn rửa chén + vòi nước | R21: CCDC | S21: Bộ | T21: 4000 | U21: 1 | V21: 4000 | W21: 24 | Y21: =V21/W21 -> 166.66667
A22: Tổng chi phí theo năm | B22: =SUM(B21:M21) -> 3684802 | P22: 20 | Q22: Hệ thống hút mùi nhỏ | R22: CCDC | S22: Bộ | T22: 5000 | U22: 1 | V22: 5000 | W22: 24 | Y22: =V22/W22 -> 208.33333
P23: 21 | Q23: Quạt thông gió | R23: CCDC | S23: Cái | T23: 2000 | U23: 1 | V23: 2000 | W23: 24 | Y23: =V23/W23 -> 83.333333
P24: 22 | Q24: Bộ dụng cụ pha chế | R24: CCDC | S24: Bộ | T24: 6000 | U24: 1 | V24: 6000 | W24: 24 | Y24: =V24/W24 -> 250
A25: 3.7.3 Dựa báo lợi nhuận | P25: 23 | Q25: Kệ để ly, tách, đĩa | R25: CCDC | S25: Cái | T25: 1500 | U25: 1 | V25: 1500 | W25: 24 | Y25: =V25/W25 -> 62.5
P26: 24 | Q26: Bàn pha chế inox | R26: CCDC | S26: Cái | T26: 6000 | U26: 1 | V26: 6000 | W26: 24 | Y26: =V26/W26 -> 250
P27: 25 | Q27: Cân điện tử mini | R27: CCDC | S27: Cái | T27: 1000 | U27: 1 | V27: 1000 | W27: 24 | Y27: =V27/W27 -> 41.666667
P28: 26 | Q28: Bộ dao, thớt, khay chuẩn bị nguyên liệu | R28: CCDC | S28: Bộ | T28: 1500 | U28: 1 | V28: 1500 | W28: 24 | Y28: =V28/W28 -> 62.5
P29: 27 | Q29: Khay đựng topping / khay inox lạnh | R29: CCDC | S29: Bộ | T29: 2000 | U29: 2 | V29: 4000 | W29: 24 | Y29: =V29/W29 -> 166.66667
P30: 28 | Q30: Kệ trưng bày sách | R30: CCDC | S30: Cái | T30: 2000 | U30: 4 | V30: 8000 | W30: 24 | Y30: =V30/W30 -> 333.33333
P31: 29 | Q31: Sách,Truyện | R31: CCDC | S31: Cuốn | T31: 100 | U31: 400 | V31: 40000 | W31: 24 | Y31: =V31/W31 -> 1666.6667
P32: 32 | Q32: Màn hình TV | R32: CCDC | S32: Cái | T32: 8000 | U32: 1 | V32: 8000 | W32: 24 | Y32: =V32/W32 -> 333.33333
P33: 33 | Q33: Loa Bluetooth | R33: CCDC | S33: Bộ | T33: 2000 | U33: 1 | V33: 2000 | W33: 24 | Y33: =V33/W33 -> 83.333333
A34: Nguyên vật liệu | C34: T9 | D34: T10 | E34: T11 | F34: T12 | G34: T1 | H34: T2 | I34: T3 | J34: T4 | K34: T5 | L34: T6 | M34: T7 | N34: T8 | P34: 34 | Q34: Đèn đọc sách | R34: CCDC | S34: Bộ | T34: 2000 | U34: 10 | V34: 2000 | W34: 24 | Y34: =V34/W34 -> 83.333333
A35: Cà phê rang xay (phin) | B35: Giá mua | C35: 220 | D35: 220 | E35: 221 | F35: 221 | G35: 222 | H35: 222 | I35: 223 | J35: 223 | K35: 224 | L35: 225 | M35: 225 | N35: 226 | P35: 36 | Q35: Bảng thông báo / menu | R35: CCDC | S35: Cái | T35: 700 | U35: 2 | V35: 1400 | W35: 24 | Y35: =V35/W35 -> 58.333333
B36: Khối lượng (kg) | C36: 80 | D36: 80 | E36: 80 | F36: 80 | G36: 80 | H36: 80 | I36: 80 | J36: 80 | K36: 80 | L36: 80 | M36: 80 | N36: 80 | P36: 37 | Q36: Máy điều hòa treo tường | R36: CCDC | S36: Cái | T36: 12000 | U36: 2 | V36: 24000 | W36: 24 | Y36: =V36/W36 -> 1000
B37: Thành tiền | C37: =C35 *C36 -> 17600 | D37: =D35 *D36 -> 17600 | E37: =E35 *E36 -> 17680 | F37: =F35 *F36 -> 17680 | G37: =G35 *G36 -> 17760 | H37: =H35 *H36 -> 17760 | I37: =I35 *I36 -> 17840 | J37: =J35 *J36 -> 17840 | ... N37: =N35 *N36 -> 18080 | P37: 38 | Q37: Quạt treo tường bổ trợ | R37: CCDC | S37: Cái | T37: 1200 | U37: 2 | V37: 2400 | W37: 24 | Y37: =V37/W37 -> 100
A38: Cà phê hạt espresso | B38: Giá mua | C38: 310 | D38: 310 | E38: 311 | F38: 311 | G38: 312 | H38: 312 | I38: 313 | J38: 313 | K38: 314 | L38: 315 | M38: 315 | N38: 316 | P38: 39 | Q38: Bình chữa cháy mini (CO2) | R38: CCDC | S38: Cái | T38: 500 | U38: 2 | V38: 1000 | W38: 24 | Y38: =V38/W38 -> 41.666667
B39: Khối lượng (kg) | C39: 45 | D39: 45 | E39: 45 | F39: 45 | G39: 45 | H39: 45 | I39: 45 | J39: 45 | K39: 45 | L39: 45 | M39: 45 | N39: 45 | P39: 40 | Q39: Thùng rác inox nắp đạp | R39: CCDC | S39: Cái | T39: 400 | U39: 3 | V39: 1200 | W39: 24 | Y39: =V39/W39 -> 50
B40: Thành tiền | C40: =C38*C39 -> 13950 | D40: =D38*D39 -> 13950 | E40: =E38*E39 -> 13995 | F40: =F38*F39 -> 13995 | G40: =G38*G39 -> 14040 | H40: =H38*H39 -> 14040 | I40: =I38*I39 -> 14085 | J40: =J38*J39 -> 14085 | ... N40: =N38*N39 -> 14220 | P40: 41 | Q40: Bàn thu ngân | R40: CCDC | S40: Cái | T40: 6000 | U40: 1 | V40: 6000 | W40: 24 | Y40: =V40/W40 -> 250
A41: Sữa đặc | B41: Giá mua | C41: 28 | D41: 28 | E41: 28 | F41: 29 | G41: 30 | H41: 30 | I41: 45805 | J41: 45805 | K41: 45805 | L41: 28 | M41: 28 | N41: 28 | P41: 42 | Q41: Máy tính POS cảm ứng | R41: CCDC | S41: Bộ | T41: 15000 | U41: 1 | V41: 15000 | W41: 24 | Y41: =V41/W41 -> 625
B42: Khối lượng (lon) | C42: 100 | D42: 100 | E42: 100 | F42: 100 | G42: 100 | H42: 100 | I42: 100 | J42: 100 | K42: 100 | L42: 100 | M42: 100 | N42: 100 | P42: 43 | Q42: Máy in bill nhiệt | R42: CCDC | S42: Cái | T42: 3000 | U42: 1 | V42: 3000 | W42: 24 | Y42: =V42/W42 -> 125
...

Sheet giá bán sp
C3: Bảng 3.4.2 Giá bán sản phẩm
B5: STT | C5: Sản phẩm | D5: Giá bán của DN (10.000đ) | E5: Giá bán của đối thủ (10.000đ)
B6: 1 | C6: Cà phê đen | D6: 30 | E6: 35
B7: 2 | C7: Cà phê sữa | D7: 35 | E7: 38
B8: 3 | C8: Espresso | D8: 33 | E8: 35
B9: 4 | C9: Americano | D9: 35 | E9: 35
B10: 5 | C10: Bạc Xỉu | D10: 38 | E10: 40
B11: 6 | C11: Trà hoa quả | D11: 42 | E11: 55
B12: 7 | C12: Trà đào cam sả | D12: 40 | E12: 55
B13: 8 | C13: Trà chanh leo | D13: 38 | E13: 50
B14: 9 | C14: Trà sen vàng | D14: 45 | E14: 45
B15: 10 | C15: Trà sữa olong đường đen | D15: 45 | E15: 55
B16: 11 | C16: Trà sữa olong matcha | D16: 45 | E16: 55
B17: 12 | C17: Trà sữa truyền thống | D17: 30 | E17: 45
... B19: 14 | C19: Trà táo/cam quế | D19: 40 | E19: 48
B20: 15 | C20: Trà lựu việt quất | D20: 40 | E20: 45-50
B21: 16 | C21: Trà dâu tằm | D21: 40 | E21: 45
B22: 17 | C22: Nước ép | D22: 35 | E22: 50
B23: 18 | C23: Sinh tố bơ | D23: 45 | E23: 55
B24: 19 | C24: Sinh tố xoài | D24: 35 | E24: 40
B25: 20 | C25: Sinh tố dâu | D25: 45 | E25: 48
B26: 21 | C26: Matcha đá xay | D26: 35 | E26: 40
B27: 22 | C27: Socola đá xay | D27: 35 | E27: 42
B28: 23 | C28: Cookies & cream đá xay | D28: 45 | E28: 52
B29: 24 | C29: Ca cao nóng | D29: 35 | E29: 38
B30: 25 | C30: Trà gừng mật ong | D30: 30 | E30: 35
B31: 26 | C31: Trà hoa cúc | D31: 30 | E31: 35
B32: 27 | C32: Combo học tập/ nghỉ ngắn | D32: 100 | E32: 110

Sheet Doanh thu
A1: Sản phẩm | B1: Chỉ tiêu | C1: 2025-2026
C2: T9 | D2: T10 | E2: T11 | F2: T12 | G2: T1 | H2: T2 | I2: T3 | J2: T4 | K2: T5 | L2: T6 | M2: T7 | N2: T8
A3: Cà phê đen | B3: Sản lượng | C3: 750 | D3: 850 | E3: 755 | F3: 1200 | G3: 1222 | H3: 1250 | I3: 1224 | J3: 1125 | K3: 1185 | L3: 1195 | M3: 1191 | N3: 1100
B4: Giá bán (nghìn vnđ) | C4: 30 | D4: 30 | E4: 30 | F4: 30 | G4: 30 | H4: 30 | I4: 30 | J4: 30 | K4: 30 | L4: 30 | M4: 30 | N4: 30
B5: Doanh thu (nghìn vnđ) | C5: =PRODUCT(C4,C3) -> 22500 | D5: =PRODUCT(D4,D3) -> 25500 | E5: =PRODUCT(E4,E3) -> 22650 | F5: =PRODUCT(F4,F3) -> 36000 | G5: =PRODUCT(G4,G3) -> 36660 | H5: =PRODUCT(H4,H3) -> 37500 | I5: =PRODUCT(I4,I3) -> 36720 | J5: =PRODUCT(J4,J3) -> 33750 | ... N5: =PRODUCT(N4,N3) -> 33000
A6: Cà phê sữa | B6: Sản lượng | C6: 750 | D6: 850 | E6: 755 | F6: 1200 | G6: 1223 | H6: 1226 | I6: 1227 | J6: 1231 | K6: 1186 | L6: 1187 | M6: 1188 | N6: 1110
B7: Giá bán (nghìn vnđ) | C7: 35 | D7: 35 | E7: 35 | F7: 35 | G7: 35 | H7: 35 | I7: 35 | J7: 35 | K7: 35 | L7: 35 | M7: 35 | N7: 35
B8: Doanh thu (nghìn vnđ) | C8: =PRODUCT(C7,C6) -> 26250 | D8: =PRODUCT(D7,D6) -> 29750 | E8: =PRODUCT(E7,E6) -> 26425 | F8: =PRODUCT(F7,F6) -> 42000 | G8: =PRODUCT(G7,G6) -> 42805 | H8: =PRODUCT(H7,H6) -> 42910 | I8: =PRODUCT(I7,I6) -> 42945 | J8: =PRODUCT(J7,J6) -> 43085 | ... N8: =PRODUCT(N7,N6) -> 38850
A9: Espresso | B9: Sản lượng | C9: 1000 | D9: 1110 | E9: 1112 | F9: 1115 | G9: 1120 | H9: 1121 | I9: 1123 | J9: 1125 | K9: 1126 | L9: 1100 | M9: 1110 | N9: 1100
B10: Giá bán (nghìn vnđ) | C10: 33 | D10: 33 | E10: 33 | F10: 33 | G10: 33 | H10: 33 | I10: 33 | J10: 33 | K10: 33 | L10: 33 | M10: 33 | N10: 33
B11: Doanh thu (nghìn vnđ) | C11: =PRODUCT(C10,C9) -> 33000 | D11: =PRODUCT(D10,D9) -> 36630 | E11: =PRODUCT(E10,E9) -> 36696 | F11: =PRODUCT(F10,F9) -> 36795 | G11: =PRODUCT(G10,G9) -> 36960 | H11: =PRODUCT(H10,H9) -> 36993 | I11: =PRODUCT(I10,I9) -> 37059 | J11: =PRODUCT(J10,J9) -> 37125 | ... N11: =PRODUCT(N10,N9) -> 36300
A12: Americano | B12: Sản lượng | C12: 750 | D12: 785 | E12: 765 | F12: 1021 | G12: 1025 | H12: 1030 | I12: 1040 | J12: 1100 | K12: 1111 | L12: 1113 | M12: 1115 | N12: 1117
B13: giá bán (nghìn vnđ) | C13: 35 | D13: 35 | E13: 35 | F13: 35 | G13: 35 | H13: 35 | I13: 35 | J13: 35 | K13: 35 | L13: 35 | M13: 35 | N13: 35
B14: Doanh thu (nghìn vnđ) | C14: =PRODUCT(C13,C12) -> 26250 | D14: =PRODUCT(D13,D12) -> 27475 | E14: =PRODUCT(E13,E12) -> 26775 | F14: =PRODUCT(F13,F12) -> 35735 | G14: =PRODUCT(G13,G12) -> 35875 | H14: =PRODUCT(H13,H12) -> 36050 | I14: =PRODUCT(I13,I12) -> 36400 | J14: =PRODUCT(J13,J12) -> 38500 | ... N14: =PRODUCT(N13,N12) -> 39095
A15: Bạc Xỉu | B15: Sản lượng | C15: 750 | D15: 755 | E15: 789 | F15: 800 | G15: 850 | H15: 860 | I15: 870 | J15: 900 | K15: 800 | L15: 750 | M15: 820 | N15: 818
B16: giá bán (nghìn vnđ) | C16: 38 | D16: 38 | E16: 38 | F16: 38 | G16: 38 | H16: 38 | I16: 38 | J16: 38 | K16: 38 | L16: 38 | M16: 38 | N16: 38
B17: Doanh thu (nghìn vnđ) | C17: =PRODUCT(C16,C15) -> 28500 | D17: =PRODUCT(D16,D15) -> 28690 | E17: =PRODUCT(E16,E15) -> 29982 | F17: =PRODUCT(F16,F15) -> 30400 | G17: =PRODUCT(G16,G15) -> 32300 | H17: =PRODUCT(H16,H15) -> 32680 | I17: =PRODUCT(I16,I15) -> 33060 | J17: =PRODUCT(J16,J15) -> 34200 | ... N17: =PRODUCT(N16,N15) -> 31084
A18: Trà hoa quả | B18: Sản lượng | C18: 500 | D18: 555 | E18: 565 | F18: 575 | G18: 600 | H18: 685 | I18: 785 | J18: 800 | K18: 700 | L18: 777 | M18: 555 | N18: 651
B19: giá bán (nghìn vnđ) | C19: 42 | D19: 42 | E19: 42 | F19: 42 | G19: 42 | H19: 42 | I19: 42 | J19: 42 | K19: 42 | L19: 42 | M19: 42 | N19: 42
B20: Doanh thu nghìn vnđ) | C20: =PRODUCT(C19,C18) -> 21000 | D20: =PRODUCT(D19,D18) -> 23310 | E20: =PRODUCT(E19,E18) -> 23730 | F20: =PRODUCT(F19,F18) -> 24150 | G20: =PRODUCT(G19,G18) -> 25200 | H20: =PRODUCT(H19,H18) -> 28770 | I20: =PRODUCT(I19,I18) -> 32970 | J20: =PRODUCT(J19,J18) -> 33600 | ... N20: =PRODUCT(N19,N18) -> 27342
A21: Trà đào cam sả | B21: Sản lượng | C21: 555 | D21: 650 | E21: 654 | F21: 864 | G21: 845 | H21: 890 | I21: 800 | J21: 700 | K21: 666 | L21: 678 | M21: 697 | N21: 631
B22: giá bán (nghìn vnđ) | C22: 40 | D22: 40 | E22: 40 | F22: 40 | G22: 40 | H22: 40 | I22: 40 | J22: 40 | K22: 40 | L22: 40 | M22: 40 | N22: 40
B23: Doanh thu nghìn vnđ) | C23: =PRODUCT(C22,C21) -> 22200 | D23: =PRODUCT(D22,D21) -> 26000 | E23: =PRODUCT(E22,E21) -> 26160 | F23: =PRODUCT(F22,F21) -> 34560 | G23: =PRODUCT(G22,G21) -> 33800 | H23: =PRODUCT(H22,H21) -> 35600 | I23: =PRODUCT(I22,I21) -> 32000 | J23: =PRODUCT(J22,J21) -> 28000 | ... N23: =PRODUCT(N22,N21) -> 25240
A24: Trà chanh leo | B24: Sản lượng | C24: 190 | D24: 125 | E24: 102 | F24: 123 | G24: 185 | H24: 154 | I24: 116 | J24: 131 | K24: 196 | L24: 148 | M24: 200 | N24: 162
B25: giá bán (nghìn vnđ) | C25: 38 | D25: 38 | E25: 38 | F25: 38 | G25: 38 | H25: 38 | I25: 38 | J25: 38 | K25: 38 | L25: 38 | M25: 38 | N25: 38
B26: Doanh thu nghìn vnđ) | C26: =PRODUCT(C25,C24) -> 7220 | D26: =PRODUCT(D25,D24) -> 4750 | E26: =PRODUCT(E25,E24) -> 3876 | F26: =PRODUCT(F25,F24) -> 4674 | G26: =PRODUCT(G25,G24) -> 7030 | H26: =PRODUCT(H25,H24) -> 5852 | I26: =PRODUCT(I25,I24) -> 4408 | J26: =PRODUCT(J25,J24) -> 4978 | ... N26: =PRODUCT(N25,N24) -> 6156
A27: Trà sen vàng | B27: Sản lượng | C27: 116 | D27: 170 | E27: 161 | F27: 115 | G27: 157 | H27: 174 | I27: 136 | J27: 130 | K27: 187 | L27: 194 | M27: 125 | N27: 180
B28: giá bán (nghìn vnđ) | C28: 45 | D28: 45 | E28: 45 | F28: 45 | G28: 45 | H28: 45 | I28: 45 | J28: 45 | K28: 45 | L28: 45 | M28: 45 | N28: 45
B29: Doanh thu nghìn vnđ) | C29: =PRODUCT(C28,C27) -> 5220 | D29: =PRODUCT(D28,D27) -> 7650 | E29: =PRODUCT(E28,E27) -> 7245 | F29: =PRODUCT(F28,F27) -> 5175 | G29: =PRODUCT(G28,G27) -> 7065 | H29: =PRODUCT(H28,H27) -> 7830 | I29: =PRODUCT(I28,I27) -> 6120 | J29: =PRODUCT(J28,J27) -> 5850 | ... N29: =PRODUCT(N28,N27) -> 8100
A30: Trà sữa olong đường đen | B30: Sản lượng | C30: 100 | D30: 100 | E30: 100 | F30: 100 | G30: 100 | H30: 100 | I30: 100 | J30: 100 | K30: 100 | L30: 100 | M30: 100 | N30: 100
B31: giá bán (nghìn vnđ) | C31: 45 | D31: 45 | E31: 45 | F31: 45 | G31: 45 | H31: 45 | I31: 45 | J31: 45 | K31: 45 | L31: 45 | M31: 45 | N31: 45
B32: Doanh thu nghìn vnđ) | C32: =PRODUCT(C31,C30) -> 4500 | D32: =PRODUCT(D31,D30) -> 4500 | E32: =PRODUCT(E31,E30) -> 4500 | F32: =PRODUCT(F31,F30) -> 4500 | G32: =PRODUCT(G31,G30) -> 4500 | H32: =PRODUCT(H31,H30) -> 4500 | I32: =PRODUCT(I31,I30) -> 4500 | J32: =PRODUCT(J31,J30) -> 4500 | ... N32: =PRODUCT(N31,N30) -> 4500
A33: Trà sữa olong matcha | B33: Sản lượng | C33: 176 | D33: 116 | E33: 111 | F33: 181 | G33: 171 | H33: 192 | I33: 200 | J33: 157 | K33: 188 | L33: 134 | M33: 122 | N33: 100
B34: giá bán (nghìn vnđ) | C34: 45 | D34: 45 | E34: 45 | F34: 45 | G34: 45 | H34: 45 | I34: 45 | J34: 45 | K34: 45 | L34: 45 | M34: 45 | N34: 45
B35: Doanh thu nghìn vnđ) | C35: =PRODUCT(C34,C33) -> 7920 | D35: =PRODUCT(D34,D33) -> 5220 | E35: =PRODUCT(E34,E33) -> 4995 | F35: =PRODUCT(F34,F33) -> 8145 | G35: =PRODUCT(G34,G33) -> 7695 | H35: =PRODUCT(H34,H33) -> 8640 | I35: =PRODUCT(I34,I33) -> 9000 | J35: =PRODUCT(J34,J33) -> 7065 | ... N35: =PRODUCT(N34,N33) -> 4500
A36: Trà sữa truyền thống | B36: Sản lượng | C36: 161 | D36: 131 | E36: 107 | F36: 192 | G36: 103 | H36: 198 | I36: 189 | J36: 182 | K36: 187 | L36: 152 | M36: 170 | N36: 102
B37: giá bán (nghìn vnđ) | C37: 30 | D37: 30 | E37: 30 | F37: 30 | G37: 30 | H37: 30 | I37: 30 | J37: 30 | K37: 30 | L37: 30 | M37: 30 | N37: 30
B38: Doanh thu nghìn vnđ) | C38: =PRODUCT(C37,C36) -> 4830 | D38: =PRODUCT(D37,D36) -> 3930 | E38: =PRODUCT(E37,E36) -> 3210 | F38: =PRODUCT(F37,F36) -> 5760 | G38: =PRODUCT(G37,G36) -> 3090 | H38: =PRODUCT(H37,H36) -> 5940 | I38: =PRODUCT(I37,I36) -> 5670 | J38: =PRODUCT(J37,J36) -> 5460 | ... N38: =PRODUCT(N37,N36) -> 3060
A39: Hồng trà kem cheese | B39: Sản lượng | C39: 119 | D39: 143 | E39: 168 | F39: 139 | G39: 132 | H39: 194 | I39: 175 | J39: 148 | K39: 196 | L39: 181 | M39: 185 | N39: 118
B40: giá bán (nghìn vnđ) | C40: 40 | D40: 40 | E40: 40 | F40: 40 | G40: 40 | H40: 40 | I40: 40 | J40: 40 | K40: 40 | L40: 40 | M40: 40 | N40: 40
...

Sheet vị trí công việc
A1: Vị trí/ chức danh | B1: Số lượng | C1: Người đảm nhiệm | D1: Mô tả nhiệm vụ | E1: Lương/tháng (1000đ) | F1: Tổng lương/năm (1000đ)
A2: Quản lý điều hành | B2: 1 | C2: Nguyễn Quang Huy | D2: - Chịu trách nhiệm chung về hoạt động của quán. - Quản lý tài chính (doanh thu, chi phí), báo cáo hàng ngày/tuần. - Quản lý nhân sự: Sắp xếp lịch làm việc, chấm công, giải quyết các vấn đề phát sinh. - Quản lý kho: Kiểm kê, đặt hàng nguyên vật liệu. - Chăm sóc khách hàng và xử lý phàn nàn. - Lên kế hoạch marketing, khuyến mãi. | E2: 14.000đ | F2: 168000đ
A3: Thu ngân & Phục vụ | B3: 6 | C3: Đinh Văn Thiện-Thái Gia Bảo - Nguyễn Hải Yến | D3: Chào đón khách hàng. - Ghi nhận order, giới thiệu menu và các chương trình khuyến mãi. - Thực hiện thao tác thanh toán trên máy POS. - Bưng bê, phục vụ đồ uống và đồ ăn nhẹ cho khách. - Dọn dẹp và giữ vệ sinh khu vực khách ngồi. - Hỗ trợ khách hàng trong suốt quá trình trải nghiệm tại quán. | E3: 6.500x6=39.000đ | F3: 468000đ
A4: Nhân viên pha chế | B4: 4 | C4: Nguyễn Trung Hiếu | D4: Pha chế đồ uống theo đúng công thức và tiêu chuẩn. - Tư vấn menu, giới thiệu đồ uống cho khách. - Giữ gìn vệ sinh khu vực quầy bar và các thiết bị. - Hỗ trợ Barista Trưởng kiểm tra và chuẩn bị nguyên liệu. | E4: 7.000x4 = 28.000đ | F4: 336.000đ
C5: Phạm Minh Đức
A6: Thị trường & Marketing | B6: 1 | C6: Nguyễn Hữu Dương | D6: Nghiên cứu thị trường, phân tích khách hàng và đối thủ. Xây dựng chiến lược marketing, truyền thông và quảng bá thương hiệu. Triển khai các hoạt động bán hàng, chăm sóc khách hàng và phát triển thị trường. | E6: 8.000đ | F6: 96.000đ
A7: Tổng | B7: =SUM(B2:B6) -> 12 | E7: 89.000đ | F7: 1.068.000đ

Sheet xúc tiến bán
A2: STT | B2: Các phương pháp xúc tiến | C2: Chi tiết | D2: Chi phí (1000đ)/ tháng
A3: 1 | B3: Chiến dịch quảng cáo trực tuyến | C3: GD1: 10/10–20/10: Tặng nhân dịp khai trương + quảng cáo Google, Facebook Ads GD2: 25/10–30/10`: Tổ chức trải nghiệm “Ngày học thử – uống miễn phí” GĐ3: Chạy ads thường xuyên (với nội dung sáng tạo theo trend) | D3: 10000
A4: 2 | B4: PR | C4: Viết bài chia sẻ trên fanpage sinh viên, group học tập, báo địa phương | D4: 8000
A5: 3 | B5: Xúc tiến bán | C5: GD1: 10/10-15/10: Tặng đồ uống khi đặt bàn học nhóm ≥ 3 người GD2: Mua 4 tặng 1 đồ uống | D5: 5000
A6: 4 | B6: Bán hàng cá nhân | C6: Nhân viên tư vấn combo, upsell đồ uống kèm combo phòng học | D6: 2000
A7: 5 | B7: Marketing trực tiếp | C7: Email, tin nhắn giới thiệu ưu đãi cho khách hàng cũ | D7: 1000
A8: Tổng | D8: =SUM(D7,D6,D5,D4,D3) -> 26000

Sheet Danh mục sản phẩm
A1: TT | B1: Sản phẩm | C1: Mô tả | D1: Lợi thế
A2: 1 | B2: Cà phê đen | C2: Rang xay nguyên chất từ hạt cà phê Mộc Châu, đảm bảo tiêu chuẩn VietGAP | D2: Hương vị đậm đà, nguyên bản – nguồn gốc sạch
A3: 2 | B3: Cà phê sữa | C3: Pha chế theo công thức riêng, kết hợp giữa cà phê nguyên chất và sữa đặc | D3: Hương vị cân bằng, hợp gu giới trẻ
A4: 3 | B4: Espresso | C4: Rang xay cà phê Ý nguyên chất pha bằng máy, vị đậm mạnh | D4: Dành cho người cần tỉnh táo, yêu vị cà phê nguyên bản
A5: 4 | B5: Americano | C5: Rang xay cà phê Ý nguyên chất pha bằng máy, vị nhẹ hơn espresso | D5: Hương vị nhẹ nhàng dễ uống hơn hơn espresso
A6: 5 | B6: Bạc Xỉu | C6: Triết xuất cafe truyền thống ra và cho 1 lượng vừa đủ vào sau đó đánh bông lên và đổ sữa đặc vào. | D6: Hương vị nhẹ nhàng có chút ngọt của sữa đặc rất phù hợp nữ giới.
A7: 6 | B7: Trà hoa quả | C7: Trà tươi pha cùng trái cây tự nhiên, không phẩm màu | D7: Giải khát, tốt cho sức khỏe
A8: 7 | B8: Trà đào cam sả | C8: Trà kèm lát đào được cắt 1 cách tinh xảo và vừa miệng, 1 lát cam tươi sạch và sả tươi làm cốc trà trở nên đặc sắc hơn. | D8: Giúp giải khát, thơm, bắt trend
A9: 8 | B9: Trà chanh leo | C9: Nốt cốt chanh leo được tự tay nhân viên triết ra và được pha cùng 1 chút trà xanh . | D9: Thanh mát, hợp sinh viên
A10: 9 | B10: Trà sen vàng | C10: Lấy hạt sen là đồ decor và thưởng thức,sau đó lấy trà olong ra pha. | D10: Thanh mát, thư giãn, hợp người thích vị nhẹ
A11: 10 | B11: Trà sữa olong đường đen | C11: Trà olong pha với sữa dùng đường đen decord sau đó cho trân châu vào. | D11: Hot trend, hợp giới trẻ, dễ bán
A12: 11 | B12: Trà sữa olong matcha | C12: Trà olong kết hợp với matcha hòa cùng sữa tươi hoặc sữa béo, thêm thạch/trân châu. | D12: Hợp gu học sinh – sinh viên yêu vị trà xanh
A13: 12 | B13: Trà sữa truyền thống | C13: Trà đen hoặc olong pha với sữa, ngọt vừa. | D13: Giá rẻ, dễ uống, hợp nhiều đối tượng
... A28: 27 | B28: Combo học tập/ nghỉ ngắn | C28: Gói combo gồm đồ uống + không gian học tập hoặc nghỉ ngắn trong 2 giờ | D28: Mô hình mới lạ, thu hút sinh viên và nhân viên văn phòng

Sheet Bảng lợi nhuận
A1: Bảng 3.7.3 Ước tính lợi nhuận
A2: Chi phí | B2: 2025-2026
B3: T9 | C3: T10 | D3: T11 | E3: T12 | F3: T1 | G3: T2 | H3: T3 | I3: T4 | J3: T5 | K3: T6 | L3: T7 | M3: T8
A4: Doanh thu | B4: ='Doanh thu'!C84 -> 399155 | C4: ='Doanh thu'!D84 -> 426070 | D4: ='Doanh thu'!E84 -> 422344 | E4: ='Doanh thu'!F84 -> 486874 | F4: ='Doanh thu'!G84 -> 500760 | G4: ='Doanh thu'!H84 -> 511145 | H4: ='Doanh thu'!I84 -> 563612 | I4: ='Doanh thu'!J84 -> 590758 | ... M4: ='Doanh thu'!N84 -> 501977 | N4: =SUM(B4:M4) -> 6022184
A5: Chi phí | B5: ='Ước tính chi phí'!B21 -> 320492 | C5: ='Ước tính chi phí'!C21 -> 305343 | D5: ='Ước tính chi phí'!D21 -> 304501 | E5: ='Ước tính chi phí'!E21 -> 304816 | F5: ='Ước tính chi phí'!F21 -> 306112 | G5: ='Ước tính chi phí'!G21 -> 306199 | H5: ='Ước tính chi phí'!H21 -> 305732 | I5: ='Ước tính chi phí'!I21 -> 305843 | ... M5: ='Ước tính chi phí'!M21 -> 306491 | N5: =SUM(B5:M5) -> 3684802
A6: Lợi nhuận | B6: =B4-B5 -> 78663 | C6: =C4-C5 -> 120727 | D6: =D4-D5 -> 117843 | E6: =E4-E5 -> 182058 | F6: =F4-F5 -> 194648 | G6: =G4-G5 -> 204946 | H6: =H4-H5 -> 257880 | I6: =I4-I5 -> 284915 | ... M6: =M4-M5 -> 195486 | N6: =SUM(B6:M6) -> 2337382
A7: Tổng Lợi nhuận theo năm (nghìn vnđ) | B7: =SUM(C6:M6) -> 2258719
A8: Tỷ suất lợi nhuận/ doanh thu ROS | B8: =SUM(B6:M6)/SUM(B4:M4)*100 -> 38.812863
A9: Tỷ suất lợi nhuận/ vốn đầu tư ROI | B9: =SUM(B6:M6)/SUM(B5:M5)*100 -> 63.433042

Sheet ước tính vốn
B2: Bảng 3.7.4.1 Ước tính vốn khởi nghiệp | G2: Loại Nguồn vốn | H2: Nguồn | I2: Số tiền | J2: Diễn giải
B3: Chỉ tiêu | C3: số tiền (1000đ) | D3: Diễn giải | G3: Vốn chủ sở hữu | H3: Nguyễn Quang Huy | I3: 93000 | J3: tích góp khi đi làm
B4: 1. Vốn cố định | C4: 327165 | D4: Vốn ban đầu cho quán cafe | H4: Đinh Văn Thiện | I4: 93000 | J4: tích góp khi đi làm
B5: phí đkkd | C5: 200 | H5: Thái Gia Bảo | I5: 93000 | J5: tích góp khi đi làm
B6: sửa chữa mặt bằng | C6: 50000 | H6: Nguyễn Hải Yến | I6: 93000 | J6: tích góp khi đi làm
B7: mua trang thiết bị | C7: 276965 | H7: Nguyễn Hữu Dương | I7: 93000 | J7: tích góp khi đi làm
B8: 2. Vốn lưu động | C8: 275545 | H8: Phạm Minh Đức | I8: 93000 | J8: tích góp khi đi làm
B9: Thuê mặt bằng | C9: 100000 | H9: Nguyễn Quang Hiếu | I9: 93000 | J9: tích góp khi đi làm
B10: Trả lương | C10: 55500 | G10: Vốn vay | I10: 0
B11: Thuế môn bài | C11: 1000 | G11: Tổng ( nghìn vnđ) | I11: =SUM(I3:I10) -> 651000
B12: Marketing | C12: 26000 | G12: TỔNG | J12: =C17 -> 646210
B13: ĐIện, nước, vpp | C13: 7000
B14: Khác | C14: 2000
B15: cf nhập hàng | C15: 84045
B16: 3. Vốn dự phòng | C16: 43500
B17: Tổng vốn khởi nghiệp | C17: =C4+C8+C16 -> 646210

Sheet rủi ro
A1: Dự báo rủi ro | B1: Đánh giá mức độ ảnh hưởng | C1: Giải pháp kiểm soát, phòng ngừa và ứng phó
A2: Rủi ro cạnh tranh: Sự xuất hiện của các quán café mới, mô hình tương tự | B2: Cao | C2: - Nghiên cứu thị trường thường xuyên, đổi mới menu và không gian. - Tăng chất lượng phục vụ, tạo trải nghiệm riêng biệt (âm nhạc nhẹ, góc đọc yên tĩnh). - Duy trì mối quan hệ khách hàng thân thiết qua ưu đãi, thẻ thành viên.
A3: Rủi ro pháp lý: Thiếu giấy phép kinh doanh, vi phạm quy định về vệ sinh an toàn thực phẩm hoặc PCCC | B3: Cao | C3: - Đăng ký đầy đủ giấy phép kinh doanh, an toàn thực phẩm, PCCC. - Đào tạo nhân viên về quy định pháp luật, kiểm tra định kỳ.
A4: Rủi ro kinh tế: Giá nguyên liệu tăng, doanh thu giảm do suy thoái hoặc thay đổi xu hướng tiêu dùng | B4: Trung bình - cao | C4: - Dự trữ nguyên liệu dài hạn, chọn nhà cung cấp ổn định. - Đa dạng nguồn doanh thu (bán mang đi, cho thuê phòng học riêng). - Theo dõi chi phí, tối ưu vận hành.
A5: Rủi ro thiên tai: Mưa bão, ngập lụt ảnh hưởng hoạt động kinh doanh | B5: Thấp - trung bình | C5: - Chọn vị trí quán cao ráo, có hệ thống thoát nước tốt. - Mua bảo hiểm tài sản và rủi ro thiên tai. - Chuẩn bị kế hoạch đóng/mở linh hoạt.
A6: Rủi ro nhân sự: Nhân viên nghỉ đột xuất, phục vụ kém, gian lận tài chính | B6: Trung bình | C6: - Có chính sách đãi ngộ tốt, đào tạo kỹ năng phục vụ. - Sử dụng phần mềm quản lý bán hàng minh bạch. - Dự phòng nhân sự thay thế tạm thời.
A7: Rủi ro khách hàng: Phản hồi xấu, sự cố an toàn (mất đồ, va chạm…) | B7: Trung bình | C7: - Lắp camera an ninh, có nhân viên trực khu vực đọc – nghỉ. - Lắng nghe phản hồi khách hàng, xử lý kịp thời. - Quy định rõ nội quy sử dụng phòng đọc/nghỉ.
A8: Rủi ro sức khỏe – vệ sinh: Thực phẩm hỏng, khách ngộ độc, dịch bệnh | B8: Cao | C8: - Bảo quản nguyên liệu đúng quy trình, chọn nguồn cung uy tín. - Đảm bảo vệ sinh trong pha chế và phục vụ. - Khử khuẩn định kỳ và tuân thủ quy định y tế.
A9: Rủi ro tài chính: Thiếu vốn duy trì hoạt động giai đoạn đầu | B9: Cao | C9: - Dự phòng vốn lưu động ít nhất 3–6 tháng. - Theo dõi dòng tiền và lập kế hoạch tài chính chi tiết. - Huy động vốn từ đối tác hoặc người thân khi cần.
